File: H183-10-90-30min_1.csv
[Measurement conditions]
Sample identification,
Comment - 1,"Configuration=Bracket Flat sample, Owner=User-1, Creation date=15/02/2016 11:36:32"
Comment - 2,"Goniometer=PW3050/60 (Theta/2Theta); Minimum step size 2Theta:0.001; Minimum step size Omega:0.001"
Comment - 3,"Sample stage=PW3071/xx Bracket"
Comment - 4,"Diffractometer system=XPERT-PRO"
Comment - 5,"Measurement program=C:\PANalytical\Data Collector\Programs\Tass-10-90-30min.xrdmp, Identifier={FC66B191-8FD9-413B-BED1-E375FF3A0E03}"
Anode material,Cu
K-Alpha1 wavelength,1.5405980
K-Alpha2 wavelength,1.5444260
Ratio K-Alpha2/K-Alpha1,0.000
Divergence slit,Fixed,  1
Monochromator used,YES
Generator voltage, 40
Tube current, 30
File date and time,24/janv./2019 10:07
Unit cell,
h k l, 0 0 0
Scan axis,Gonio
Scan range,10.007000001,79.993792989
Scan step size,0.0334225
No. of points, 2094
Scan type,CONTINUOUS
Time per step,59.690
[Scan points]
Angle,Intensity
10.023711270,602.0
10.090556344,604.0
10.157401419,554.0
10.224246493,571.0
10.291091568,586.0
10.357936642,620.0
10.424781717,580.0
10.491626791,586.0
10.558471866,603.0
10.625316940,583.0
10.692162015,565.0
10.759007089,594.0
10.825852164,590.0
10.892697238,605.0
10.959542313,613.0
11.026387387,603.0
11.093232462,590.0
11.160077536,625.0
11.226922611,617.0
11.293767685,552.0
11.360612760,563.0
11.427457834,569.0
11.494302909,549.0
11.561147983,603.0
11.627993058,589.0
11.694838132,604.0
11.761683207,617.0
11.828528281,575.0
11.895373356,635.0
11.962218430,580.0
12.029063505,621.0
12.095908579,611.0
12.162753654,605.0
12.229598728,594.0
12.296443803,604.0
12.363288877,601.0
12.430133952,618.0
12.496979026,628.0
12.563824100,645.0
12.630669175,663.0
12.697514249,638.0
12.764359324,629.0
12.831204398,683.0
12.898049473,634.0
12.964894547,645.0
13.031739622,654.0
13.098584696,672.0
13.165429771,700.0
13.232274845,604.0
13.299119920,631.0
13.365964994,612.0
13.432810069,606.0
13.499655143,624.0
13.566500218,624.0
13.633345292,661.0
13.700190367,653.0
13.767035441,689.0
13.833880516,680.0
13.900725590,646.0
13.967570665,658.0
14.034415739,653.0
14.101260814,647.0
14.168105888,658.0
14.234950963,691.0
14.301796037,660.0
14.368641112,676.0
14.435486186,743.0
14.502331261,716.0
14.569176335,677.0
14.636021410,720.0
14.702866484,699.0
14.769711559,676.0
14.836556633,702.0
14.903401708,688.0
14.970246782,712.0
15.037091856,662.0
15.103936931,708.0
15.170782005,717.0
15.237627080,757.0
15.304472154,746.0
15.371317229,786.0
15.438162303,699.0
15.505007378,732.0
15.571852452,785.0
15.638697527,737.0
15.705542601,756.0
15.772387676,720.0
15.839232750,763.0
15.906077825,781.0
15.972922899,737.0
16.039767974,772.0
16.106613048,741.0
16.173458123,773.0
16.240303197,740.0
16.307148272,770.0
16.373993346,814.0
16.440838421,823.0
16.507683495,806.0
16.574528570,809.0
16.641373644,790.0
16.708218719,799.0
16.775063793,829.0
16.841908868,837.0
16.908753942,822.0
16.975599017,835.0
17.042444091,851.0
17.109289166,843.0
17.176134240,864.0
17.242979315,822.0
17.309824389,868.0
17.376669464,902.0
17.443514538,864.0
17.510359612,793.0
17.577204687,895.0
17.644049761,832.0
17.710894836,802.0
17.777739910,856.0
17.844584985,847.0
17.911430059,831.0
17.978275134,879.0
18.045120208,766.0
18.111965283,819.0
18.178810357,852.0
18.245655432,813.0
18.312500506,838.0
18.379345581,859.0
18.446190655,876.0
18.513035730,855.0
18.579880804,919.0
18.646725879,822.0
18.713570953,888.0
18.780416028,910.0
18.847261102,873.0
18.914106177,833.0
18.980951251,848.0
19.047796326,885.0
19.114641400,795.0
19.181486475,890.0
19.248331549,864.0
19.315176624,843.0
19.382021698,892.0
19.448866773,868.0
19.515711847,877.0
19.582556922,890.0
19.649401996,814.0
19.716247071,846.0
19.783092145,814.0
19.849937219,841.0
19.916782294,810.0
19.983627368,839.0
20.050472443,853.0
20.117317517,824.0
20.184162592,874.0
20.251007666,818.0
20.317852741,820.0
20.384697815,802.0
20.451542890,842.0
20.518387964,804.0
20.585233039,862.0
20.652078113,850.0
20.718923188,793.0
20.785768262,826.0
20.852613337,860.0
20.919458411,834.0
20.986303486,837.0
21.053148560,848.0
21.119993635,850.0
21.186838709,815.0
21.253683784,801.0
21.320528858,828.0
21.387373933,850.0
21.454219007,831.0
21.521064082,809.0
21.587909156,850.0
21.654754231,798.0
21.721599305,832.0
21.788444380,854.0
21.855289454,814.0
21.922134529,770.0
21.988979603,865.0
22.055824678,798.0
22.122669752,772.0
22.189514827,768.0
22.256359901,822.0
22.323204975,804.0
22.390050050,770.0
22.456895124,820.0
22.523740199,807.0
22.590585273,780.0
22.657430348,814.0
22.724275422,718.0
22.791120497,796.0
22.857965571,770.0
22.924810646,857.0
22.991655720,735.0
23.058500795,784.0
23.125345869,757.0
23.192190944,748.0
23.259036018,745.0
23.325881093,757.0
23.392726167,762.0
23.459571242,777.0
23.526416316,788.0
23.593261391,657.0
23.660106465,686.0
23.726951540,728.0
23.793796614,697.0
23.860641689,737.0
23.927486763,724.0
23.994331838,699.0
24.061176912,728.0
24.128021987,708.0
24.194867061,729.0
24.261712136,766.0
24.328557210,739.0
24.395402285,705.0
24.462247359,765.0
24.529092434,694.0
24.595937508,748.0
24.662782583,752.0
24.729627657,714.0
24.796472731,740.0
24.863317806,661.0
24.930162880,714.0
24.997007955,723.0
25.063853029,716.0
25.130698104,684.0
25.197543178,709.0
25.264388253,700.0
25.331233327,708.0
25.398078402,644.0
25.464923476,701.0
25.531768551,693.0
25.598613625,720.0
25.665458700,667.0
25.732303774,686.0
25.799148849,622.0
25.865993923,681.0
25.932838998,731.0
25.999684072,655.0
26.066529147,656.0
26.133374221,684.0
26.200219296,701.0
26.267064370,717.0
26.333909445,647.0
26.400754519,637.0
26.467599594,670.0
26.534444668,634.0
26.601289743,682.0
26.668134817,666.0
26.734979892,661.0
26.801824966,672.0
26.868670041,642.0
26.935515115,620.0
27.002360190,648.0
27.069205264,665.0
27.136050339,616.0
27.202895413,665.0
27.269740487,624.0
27.336585562,628.0
27.403430636,648.0
27.470275711,629.0
27.537120785,600.0
27.603965860,616.0
27.670810934,645.0
27.737656009,674.0
27.804501083,677.0
27.871346158,632.0
27.938191232,640.0
28.005036307,674.0
28.071881381,638.0
28.138726456,592.0
28.205571530,659.0
28.272416605,607.0
28.339261679,610.0
28.406106754,616.0
28.472951828,572.0
28.539796903,607.0
28.606641977,631.0
28.673487052,614.0
28.740332126,654.0
28.807177201,628.0
28.874022275,622.0
28.940867350,600.0
29.007712424,604.0
29.074557499,541.0
29.141402573,605.0
29.208247648,629.0
29.275092722,620.0
29.341937797,649.0
29.408782871,592.0
29.475627946,648.0
29.542473020,597.0
29.609318095,562.0
29.676163169,596.0
29.743008243,603.0
29.809853318,637.0
29.876698392,612.0
29.943543467,590.0
30.010388541,613.0
30.077233616,578.0
30.144078690,572.0
30.210923765,614.0
30.277768839,578.0
30.344613914,575.0
30.411458988,580.0
30.478304063,611.0
30.545149137,552.0
30.611994212,608.0
30.678839286,556.0
30.745684361,577.0
30.812529435,515.0
30.879374510,607.0
30.946219584,633.0
31.013064659,577.0
31.079909733,601.0
31.146754808,594.0
31.213599882,589.0
31.280444957,561.0
31.347290031,582.0
31.414135106,559.0
31.480980180,579.0
31.547825255,600.0
31.614670329,533.0
31.681515404,568.0
31.748360478,580.0
31.815205553,552.0
31.882050627,571.0
31.948895702,570.0
32.015740776,562.0
32.082585851,551.0
32.149430925,545.0
32.216275999,533.0
32.283121074,592.0
32.349966148,560.0
32.416811223,568.0
32.483656297,573.0
32.550501372,568.0
32.617346446,616.0
32.684191521,560.0
32.751036595,572.0
32.817881670,548.0
32.884726744,549.0
32.951571819,548.0
33.018416893,566.0
33.085261968,533.0
33.152107042,573.0
33.218952117,513.0
33.285797191,548.0
33.352642266,494.0
33.419487340,548.0
33.486332415,538.0
33.553177489,589.0
33.620022564,516.0
33.686867638,519.0
33.753712713,555.0
33.820557787,544.0
33.887402862,540.0
33.954247936,545.0
34.021093011,545.0
34.087938085,555.0
34.154783160,493.0
34.221628234,524.0
34.288473309,530.0
34.355318383,570.0
34.422163458,564.0
34.489008532,548.0
34.555853607,490.0
34.622698681,519.0
34.689543755,557.0
34.756388830,514.0
34.823233904,517.0
34.890078979,564.0
34.956924053,529.0
35.023769128,493.0
35.090614202,537.0
35.157459277,556.0
35.224304351,507.0
35.291149426,530.0
35.357994500,511.0
35.424839575,461.0
35.491684649,530.0
35.558529724,490.0
35.625374798,516.0
35.692219873,535.0
35.759064947,489.0
35.825910022,519.0
35.892755096,517.0
35.959600171,562.0
36.026445245,515.0
36.093290320,493.0
36.160135394,485.0
36.226980469,510.0
36.293825543,472.0
36.360670618,506.0
36.427515692,519.0
36.494360767,577.0
36.561205841,600.0
36.628050916,1277.0
36.694895990,3664.0
36.761741065,1717.0
36.828586139,726.0
36.895431214,596.0
36.962276288,516.0
37.029121362,503.0
37.095966437,527.0
37.162811511,474.0
37.229656586,490.0
37.296501660,483.0
37.363346735,500.0
37.430191809,500.0
37.497036884,516.0
37.563881958,493.0
37.630727033,486.0
37.697572107,538.0
37.764417182,502.0
37.831262256,509.0
37.898107331,496.0
37.964952405,472.0
38.031797480,457.0
38.098642554,504.0
38.165487629,473.0
38.232332703,462.0
38.299177778,507.0
38.366022852,487.0
38.432867927,499.0
38.499713001,454.0
38.566558076,493.0
38.633403150,504.0
38.700248225,482.0
38.767093299,481.0
38.833938374,477.0
38.900783448,479.0
38.967628523,439.0
39.034473597,468.0
39.101318672,487.0
39.168163746,497.0
39.235008821,509.0
39.301853895,522.0
39.368698970,500.0
39.435544044,454.0
39.502389118,495.0
39.569234193,469.0
39.636079267,520.0
39.702924342,479.0
39.769769416,468.0
39.836614491,479.0
39.903459565,468.0
39.970304640,494.0
40.037149714,472.0
40.103994789,523.0
40.170839863,428.0
40.237684938,493.0
40.304530012,472.0
40.371375087,520.0
40.438220161,490.0
40.505065236,467.0
40.571910310,465.0
40.638755385,473.0
40.705600459,453.0
40.772445534,457.0
40.839290608,445.0
40.906135683,477.0
40.972980757,492.0
41.039825832,491.0
41.106670906,467.0
41.173515981,487.0
41.240361055,458.0
41.307206130,469.0
41.374051204,480.0
41.440896279,481.0
41.507741353,476.0
41.574586428,486.0
41.641431502,437.0
41.708276577,445.0
41.775121651,508.0
41.841966726,469.0
41.908811800,488.0
41.975656874,499.0
42.042501949,488.0
42.109347023,534.0
42.176192098,579.0
42.243037172,556.0
42.309882247,618.0
42.376727321,604.0
42.443572396,812.0
42.510417470,1023.0
42.577262545,2330.0
42.644107619,4283.0
42.710952694,2098.0
42.777797768,1063.0
42.844642843,811.0
42.911487917,683.0
42.978332992,615.0
43.045178066,611.0
43.112023141,555.0
43.178868215,509.0
43.245713290,502.0
43.312558364,472.0
43.379403439,497.0
43.446248513,471.0
43.513093588,465.0
43.579938662,492.0
43.646783737,467.0
43.713628811,473.0
43.780473886,467.0
43.847318960,433.0
43.914164035,437.0
43.981009109,483.0
44.047854184,458.0
44.114699258,431.0
44.181544333,432.0
44.248389407,439.0
44.315234482,434.0
44.382079556,461.0
44.448924630,469.0
44.515769705,497.0
44.582614779,444.0
44.649459854,473.0
44.716304928,418.0
44.783150003,466.0
44.849995077,482.0
44.916840152,448.0
44.983685226,404.0
45.050530301,437.0
45.117375375,427.0
45.184220450,449.0
45.251065524,372.0
45.317910599,441.0
45.384755673,413.0
45.451600748,413.0
45.518445822,448.0
45.585290897,418.0
45.652135971,423.0
45.718981046,418.0
45.785826120,437.0
45.852671195,413.0
45.919516269,395.0
45.986361344,421.0
46.053206418,407.0
46.120051493,453.0
46.186896567,403.0
46.253741642,402.0
46.320586716,462.0
46.387431791,439.0
46.454276865,405.0
46.521121940,440.0
46.587967014,400.0
46.654812089,435.0
46.721657163,383.0
46.788502238,394.0
46.855347312,425.0
46.922192386,394.0
46.989037461,383.0
47.055882535,420.0
47.122727610,395.0
47.189572684,409.0
47.256417759,441.0
47.323262833,461.0
47.390107908,414.0
47.456952982,404.0
47.523798057,411.0
47.590643131,410.0
47.657488206,460.0
47.724333280,403.0
47.791178355,408.0
47.858023429,381.0
47.924868504,390.0
47.991713578,440.0
48.058558653,383.0
48.125403727,404.0
48.192248802,411.0
48.259093876,391.0
48.325938951,399.0
48.392784025,381.0
48.459629100,418.0
48.526474174,430.0
48.593319249,399.0
48.660164323,403.0
48.727009398,403.0
48.793854472,432.0
48.860699547,357.0
48.927544621,385.0
48.994389696,400.0
49.061234770,422.0
49.128079845,409.0
49.194924919,391.0
49.261769994,416.0
49.328615068,370.0
49.395460142,398.0
49.462305217,356.0
49.529150291,392.0
49.595995366,417.0
49.662840440,420.0
49.729685515,419.0
49.796530589,408.0
49.863375664,407.0
49.930220738,389.0
49.997065813,393.0
50.063910887,391.0
50.130755962,399.0
50.197601036,399.0
50.264446111,377.0
50.331291185,367.0
50.398136260,403.0
50.464981334,423.0
50.531826409,379.0
50.598671483,377.0
50.665516558,420.0
50.732361632,382.0
50.799206707,349.0
50.866051781,396.0
50.932896856,378.0
50.999741930,382.0
51.066587005,417.0
51.133432079,374.0
51.200277154,360.0
51.267122228,364.0
51.333967303,398.0
51.400812377,402.0
51.467657452,390.0
51.534502526,380.0
51.601347601,368.0
51.668192675,347.0
51.735037750,344.0
51.801882824,379.0
51.868727898,341.0
51.935572973,377.0
52.002418047,363.0
52.069263122,368.0
52.136108196,369.0
52.202953271,379.0
52.269798345,384.0
52.336643420,362.0
52.403488494,390.0
52.470333569,362.0
52.537178643,377.0
52.604023718,372.0
52.670868792,354.0
52.737713867,352.0
52.804558941,397.0
52.871404016,397.0
52.938249090,386.0
53.005094165,368.0
53.071939239,374.0
53.138784314,405.0
53.205629388,382.0
53.272474463,348.0
53.339319537,366.0
53.406164612,416.0
53.473009686,338.0
53.539854761,374.0
53.606699835,378.0
53.673544910,349.0
53.740389984,374.0
53.807235059,385.0
53.874080133,349.0
53.940925208,379.0
54.007770282,326.0
54.074615357,354.0
54.141460431,358.0
54.208305505,384.0
54.275150580,334.0
54.341995654,344.0
54.408840729,338.0
54.475685803,342.0
54.542530878,390.0
54.609375952,381.0
54.676221027,386.0
54.743066101,371.0
54.809911176,404.0
54.876756250,366.0
54.943601325,371.0
55.010446399,340.0
55.077291474,335.0
55.144136548,367.0
55.210981623,402.0
55.277826697,385.0
55.344671772,334.0
55.411516846,326.0
55.478361921,347.0
55.545206995,372.0
55.612052070,384.0
55.678897144,321.0
55.745742219,390.0
55.812587293,372.0
55.879432368,350.0
55.946277442,350.0
56.013122517,360.0
56.079967591,371.0
56.146812666,364.0
56.213657740,341.0
56.280502815,369.0
56.347347889,355.0
56.414192964,348.0
56.481038038,391.0
56.547883113,358.0
56.614728187,335.0
56.681573261,375.0
56.748418336,362.0
56.815263410,353.0
56.882108485,396.0
56.948953559,342.0
57.015798634,352.0
57.082643708,384.0
57.149488783,352.0
57.216333857,328.0
57.283178932,323.0
57.350024006,330.0
57.416869081,328.0
57.483714155,360.0
57.550559230,371.0
57.617404304,354.0
57.684249379,344.0
57.751094453,348.0
57.817939528,356.0
57.884784602,364.0
57.951629677,372.0
58.018474751,354.0
58.085319826,350.0
58.152164900,377.0
58.219009975,363.0
58.285855049,362.0
58.352700124,351.0
58.419545198,350.0
58.486390273,313.0
58.553235347,334.0
58.620080422,336.0
58.686925496,370.0
58.753770571,336.0
58.820615645,340.0
58.887460720,380.0
58.954305794,351.0
59.021150869,353.0
59.087995943,337.0
59.154841017,338.0
59.221686092,339.0
59.288531166,336.0
59.355376241,367.0
59.422221315,352.0
59.489066390,374.0
59.555911464,313.0
59.622756539,349.0
59.689601613,323.0
59.756446688,382.0
59.823291762,352.0
59.890136837,369.0
59.956981911,374.0
60.023826986,352.0
60.090672060,369.0
60.157517135,366.0
60.224362209,328.0
60.291207284,371.0
60.358052358,328.0
60.424897433,310.0
60.491742507,361.0
60.558587582,349.0
60.625432656,371.0
60.692277731,326.0
60.759122805,341.0
60.825967880,334.0
60.892812954,320.0
60.959658029,353.0
61.026503103,341.0
61.093348178,352.0
61.160193252,392.0
61.227038327,345.0
61.293883401,320.0
61.360728476,331.0
61.427573550,375.0
61.494418625,351.0
61.561263699,388.0
61.628108773,395.0
61.694953848,464.0
61.761798922,579.0
61.828643997,1270.0
61.895489071,1515.0
61.962334146,859.0
62.029179220,547.0
62.096024295,427.0
62.162869369,381.0
62.229714444,372.0
62.296559518,352.0
62.363404593,348.0
62.430249667,333.0
62.497094742,328.0
62.563939816,369.0
62.630784891,339.0
62.697629965,344.0
62.764475040,351.0
62.831320114,340.0
62.898165189,343.0
62.965010263,337.0
63.031855338,307.0
63.098700412,316.0
63.165545487,355.0
63.232390561,326.0
63.299235636,330.0
63.366080710,331.0
63.432925785,293.0
63.499770859,340.0
63.566615934,323.0
63.633461008,333.0
63.700306083,352.0
63.767151157,326.0
63.833996232,322.0
63.900841306,343.0
63.967686381,315.0
64.034531455,325.0
64.101376529,319.0
64.168221604,327.0
64.235066678,325.0
64.301911753,366.0
64.368756827,324.0
64.435601902,341.0
64.502446976,312.0
64.569292051,337.0
64.636137125,306.0
64.702982200,329.0
64.769827274,340.0
64.836672349,342.0
64.903517423,312.0
64.970362498,310.0
65.037207572,329.0
65.104052647,316.0
65.170897721,326.0
65.237742796,313.0
65.304587870,326.0
65.371432945,305.0
65.438278019,334.0
65.505123094,327.0
65.571968168,302.0
65.638813243,349.0
65.705658317,311.0
65.772503392,296.0
65.839348466,317.0
65.906193541,315.0
65.973038615,324.0
66.039883690,303.0
66.106728764,273.0
66.173573839,278.0
66.240418913,287.0
66.307263988,312.0
66.374109062,323.0
66.440954137,311.0
66.507799211,327.0
66.574644285,294.0
66.641489360,309.0
66.708334434,338.0
66.775179509,317.0
66.842024583,322.0
66.908869658,301.0
66.975714732,316.0
67.042559807,315.0
67.109404881,323.0
67.176249956,305.0
67.243095030,314.0
67.309940105,306.0
67.376785179,316.0
67.443630254,284.0
67.510475328,309.0
67.577320403,301.0
67.644165477,308.0
67.711010552,306.0
67.777855626,297.0
67.844700701,322.0
67.911545775,301.0
67.978390850,297.0
68.045235924,301.0
68.112080999,305.0
68.178926073,287.0
68.245771148,306.0
68.312616222,298.0
68.379461297,303.0
68.446306371,306.0
68.513151446,291.0
68.579996520,288.0
68.646841595,321.0
68.713686669,307.0
68.780531744,295.0
68.847376818,315.0
68.914221893,348.0
68.981066967,291.0
69.047912041,316.0
69.114757116,311.0
69.181602190,289.0
69.248447265,286.0
69.315292339,307.0
69.382137414,283.0
69.448982488,316.0
69.515827563,305.0
69.582672637,309.0
69.649517712,314.0
69.716362786,284.0
69.783207861,316.0
69.850052935,278.0
69.916898010,278.0
69.983743084,280.0
70.050588159,285.0
70.117433233,308.0
70.184278308,287.0
70.251123382,297.0
70.317968457,287.0
70.384813531,285.0
70.451658606,289.0
70.518503680,305.0
70.585348755,261.0
70.652193829,302.0
70.719038904,308.0
70.785883978,292.0
70.852729053,284.0
70.919574127,281.0
70.986419202,293.0
71.053264276,289.0
71.120109351,284.0
71.186954425,294.0
71.253799500,310.0
71.320644574,281.0
71.387489648,294.0
71.454334723,303.0
71.521179797,284.0
71.588024872,277.0
71.654869946,301.0
71.721715021,316.0
71.788560095,284.0
71.855405170,282.0
71.922250244,289.0
71.989095319,299.0
72.055940393,269.0
72.122785468,301.0
72.189630542,275.0
72.256475617,280.0
72.323320691,297.0
72.390165766,282.0
72.457010840,292.0
72.523855915,291.0
72.590700989,300.0
72.657546064,277.0
72.724391138,280.0
72.791236213,286.0
72.858081287,282.0
72.924926362,295.0
72.991771436,292.0
73.058616511,306.0
73.125461585,278.0
73.192306660,298.0
73.259151734,301.0
73.325996809,326.0
73.392841883,294.0
73.459686958,295.0
73.526532032,286.0
73.593377107,287.0
73.660222181,275.0
73.727067256,336.0
73.793912330,315.0
73.860757404,366.0
73.927602479,319.0
73.994447553,357.0
74.061292628,516.0
74.128137702,688.0
74.194982777,606.0
74.261827851,450.0
74.328672926,356.0
74.395518000,334.0
74.462363075,347.0
74.529208149,328.0
74.596053224,257.0
74.662898298,281.0
74.729743373,340.0
74.796588447,300.0
74.863433522,270.0
74.930278596,294.0
74.997123671,306.0
75.063968745,288.0
75.130813820,302.0
75.197658894,287.0
75.264503969,275.0
75.331349043,324.0
75.398194118,264.0
75.465039192,316.0
75.531884267,271.0
75.598729341,322.0
75.665574416,278.0
75.732419490,285.0
75.799264565,293.0
75.866109639,302.0
75.932954714,299.0
75.999799788,315.0
76.066644863,300.0
76.133489937,270.0
76.200335012,279.0
76.267180086,269.0
76.334025160,295.0
76.400870235,268.0
76.467715309,287.0
76.534560384,289.0
76.601405458,262.0
76.668250533,315.0
76.735095607,250.0
76.801940682,275.0
76.868785756,303.0
76.935630831,271.0
77.002475905,259.0
77.069320980,275.0
77.136166054,266.0
77.203011129,259.0
77.269856203,282.0
77.336701278,275.0
77.403546352,282.0
77.470391427,273.0
77.537236501,270.0
77.604081576,258.0
77.670926650,282.0
77.737771725,303.0
77.804616799,313.0
77.871461874,303.0
77.938306948,356.0
78.005152023,508.0
78.071997097,481.0
78.138842172,413.0
78.205687246,313.0
78.272532321,308.0
78.339377395,286.0
78.406222470,280.0
78.473067544,322.0
78.539912619,284.0
78.606757693,292.0
78.673602768,265.0
78.740447842,277.0
78.807292916,278.0
78.874137991,281.0
78.940983065,265.0
79.007828140,301.0
79.074673214,279.0
79.141518289,284.0
79.208363363,291.0
79.275208438,293.0
79.342053512,264.0
79.408898587,255.0
79.475743661,272.0
79.542588736,289.0
79.609433810,266.0
79.676278885,262.0
79.743123959,267.0
79.809969034,234.0
79.876814108,264.0
79.943659183,288.0
79.977081720,253.0